<sdf version='1.7'>
  <model name='mobile_arm_bot_2'>
    <plugin name='gazebo_ros2_control' filename='libgazebo_ros2_control.so'>
      <parameters>model://mobile_arm_bot_2/ros2_controllers.yaml</parameters>
    </plugin>
    <ros2_control name='FakeSystem' type='system'>
      <hardware>
        <plugin>gazebo_ros2_control/GazeboSystem</plugin>
      </hardware>
      <joint name='joint_1'>
        <command_interface name='position'/>
        <state_interface name='position'>
          <param name='initial_value'>0</param>
        </state_interface>
        <state_interface name='velocity'/>
      </joint>
      <joint name='joint_2'>
        <command_interface name='position'/>
        <state_interface name='position'>
          <param name='initial_value'>0</param>
        </state_interface>
        <state_interface name='velocity'/>
      </joint>
      <joint name='joint_3'>
        <command_interface name='position'/>
        <state_interface name='position'>
          <param name='initial_value'>0</param>
        </state_interface>
        <state_interface name='velocity'/>
      </joint>
      <joint name='joint_4'>
        <command_interface name='position'/>
        <state_interface name='position'>
          <param name='initial_value'>0</param>
        </state_interface>
        <state_interface name='velocity'/>
      </joint>
      <joint name='gripper_base_joint'>
        <command_interface name='position'/>
        <state_interface name='position'>
          <param name='initial_value'>0</param>
        </state_interface>
        <state_interface name='velocity'/>
      </joint>
      <joint name='left_gear_joint'>
        <command_interface name='position'/>
        <state_interface name='position'>
          <param name='initial_value'>0</param>
        </state_interface>
        <state_interface name='velocity'/>
      </joint>
    </ros2_control>
    <link name='base_link'>
      <inertial>
        <pose>-0.000367 0.000116 0.022489 0 -0 0</pose>
        <mass>0.093638</mass>
        <inertia>
          <ixx>0.00012547</ixx>
          <ixy>-2.5159e-08</ixy>
          <ixz>1.5661e-06</ixz>
          <iyy>0.00013089</iyy>
          <iyz>-1.4418e-07</iyz>
          <izz>0.00020147</izz>
        </inertia>
      </inertial>
      <collision name='base_link_collision'>
        <pose>0 0 0 0 -0 0</pose>
        <geometry>
          <mesh>
            <scale>1 1 1</scale>
            <uri>model://mobile_arm_bot_2/meshes/base_link.STL</uri>
          </mesh>
        </geometry>
      </collision>
      <visual name='base_link_visual'>
        <pose>0 0 0 0 -0 0</pose>
        <geometry>
          <mesh>
            <scale>1 1 1</scale>
            <uri>model://mobile_arm_bot_2/meshes/base_link.STL</uri>
          </mesh>
        </geometry>
      </visual>
    </link>
    <joint name='joint_1' type='revolute'>
      <pose relative_to='base_link'>0 0 0.056 0 0 -0.26189</pose>
      <parent>base_link</parent>
      <child>link_1</child>
      <axis>
        <xyz>0 0 1</xyz>
        <limit>
          <lower>0</lower>
          <upper>3.1416</upper>
          <effort>0</effort>
          <velocity>0</velocity>
        </limit>
        <dynamics>
          <spring_reference>0</spring_reference>
          <spring_stiffness>0</spring_stiffness>
        </dynamics>
      </axis>
    </joint>
    <link name='link_1'>
      <pose relative_to='joint_1'>0 0 0 0 -0 0</pose>
      <inertial>
        <pose>0.002243 0.007576 0.018765 0 -0 0</pose>
        <mass>0.072312</mass>
        <inertia>
          <ixx>4.9568e-05</ixx>
          <ixy>-1.5508e-06</ixy>
          <ixz>-6.3994e-06</ixz>
          <iyy>6.2445e-05</iyy>
          <iyz>-6.7489e-06</iyz>
          <izz>5.6938e-05</izz>
        </inertia>
      </inertial>
      <collision name='link_1_collision'>
        <pose>0 0 0 0 -0 0</pose>
        <geometry>
          <mesh>
            <scale>1 1 1</scale>
            <uri>model://mobile_arm_bot_2/meshes/link_1.STL</uri>
          </mesh>
        </geometry>
      </collision>
      <visual name='link_1_visual'>
        <pose>0 0 0 0 -0 0</pose>
        <geometry>
          <mesh>
            <scale>1 1 1</scale>
            <uri>model://mobile_arm_bot_2/meshes/link_1.STL</uri>
          </mesh>
        </geometry>
      </visual>
    </link>
    <joint name='joint_2' type='revolute'>
      <pose relative_to='link_1'>0.013919 0 0.040276 0 -0.49165 0</pose>
      <parent>link_1</parent>
      <child>link_2</child>
      <axis>
        <xyz>0 1 0</xyz>
        <limit>
          <lower>0</lower>
          <upper>3.1416</upper>
          <effort>0</effort>
          <velocity>0</velocity>
        </limit>
        <dynamics>
          <spring_reference>0</spring_reference>
          <spring_stiffness>0</spring_stiffness>
        </dynamics>
      </axis>
    </joint>
    <link name='link_2'>
      <pose relative_to='joint_2'>0 0 0 0 -0 0</pose>
      <inertial>
        <pose>-0.000129 -0.004334 0.059294 0 -0 0</pose>
        <mass>0.056532</mass>
        <inertia>
          <ixx>9.4195e-05</ixx>
          <ixy>-3.005e-10</ixy>
          <ixz>-1.4691e-09</ixz>
          <iyy>9.7021e-05</iyy>
          <iyz>-3.0019e-10</iyz>
          <izz>7.2804e-06</izz>
        </inertia>
      </inertial>
      <collision name='link_2_collision'>
        <pose>0 0 0 0 -0 0</pose>
        <geometry>
          <mesh>
            <scale>1 1 1</scale>
            <uri>model://mobile_arm_bot_2/meshes/link_2.STL</uri>
          </mesh>
        </geometry>
      </collision>
      <visual name='link_2_visual'>
        <pose>0 0 0 0 -0 0</pose>
        <geometry>
          <mesh>
            <scale>1 1 1</scale>
            <uri>model://mobile_arm_bot_2/meshes/link_2.STL</uri>
          </mesh>
        </geometry>
      </visual>
    </link>
    <joint name='joint_3' type='revolute'>
      <pose relative_to='link_2'>0 0 0.12 -0.008537 -0.072864 -0.001293</pose>
      <parent>link_2</parent>
      <child>link_3</child>
      <axis>
        <xyz>0.00129 -0.99996 -0.008631</xyz>
        <limit>
          <lower>0</lower>
          <upper>3.1416</upper>
          <effort>0</effort>
          <velocity>0</velocity>
        </limit>
        <dynamics>
          <spring_reference>0</spring_reference>
          <spring_stiffness>0</spring_stiffness>
        </dynamics>
      </axis>
    </joint>
    <link name='link_3'>
      <pose relative_to='joint_3'>0 0 0 0 -0 0</pose>
      <inertial>
        <pose>0.03808 0.013781 -0.00092 0 -0 0</pose>
        <mass>0.05696</mass>
        <inertia>
          <ixx>1.1086e-05</ixx>
          <ixy>-9.9972e-07</ixy>
          <ixz>1.4846e-06</ixz>
          <iyy>6.7149e-05</iyy>
          <iyz>5.5761e-08</iyz>
          <izz>6.3613e-05</izz>
        </inertia>
      </inertial>
      <collision name='link_3_collision'>
        <pose>0 0 0 0 -0 0</pose>
        <geometry>
          <mesh>
            <scale>1 1 1</scale>
            <uri>model://mobile_arm_bot_2/meshes/link_3.STL</uri>
          </mesh>
        </geometry>
      </collision>
      <visual name='link_3_visual'>
        <pose>0 0 0 0 -0 0</pose>
        <geometry>
          <mesh>
            <scale>1 1 1</scale>
            <uri>model://mobile_arm_bot_2/meshes/link_3.STL</uri>
          </mesh>
        </geometry>
      </visual>
    </link>
    <joint name='joint_4' type='revolute'>
      <pose relative_to='link_3'>0.077872 0.013612 -0.007225 0.000235 0.017066 0.001272</pose>
      <parent>link_3</parent>
      <child>link_4</child>
      <axis>
        <xyz>0.99996 0.000241 -0.009107</xyz>
        <limit>
          <lower>0</lower>
          <upper>3.1416</upper>
          <effort>0</effort>
          <velocity>0</velocity>
        </limit>
        <dynamics>
          <spring_reference>0</spring_reference>
          <spring_stiffness>0</spring_stiffness>
        </dynamics>
      </axis>
    </joint>
    <link name='link_4'>
      <pose relative_to='joint_4'>0 0 0 0 -0 0</pose>
      <inertial>
        <pose>0.029998 -0.005741 0.004816 0 -0 0</pose>
        <mass>0.018176</mass>
        <inertia>
          <ixx>2.8956e-06</ixx>
          <ixy>6.016e-07</ixy>
          <ixz>1.9471e-08</ixz>
          <iyy>5.3577e-06</iyy>
          <iyz>-1.8766e-08</iyz>
          <izz>4.262e-06</izz>
        </inertia>
      </inertial>
      <collision name='link_4_collision'>
        <pose>0 0 0 0 -0 0</pose>
        <geometry>
          <mesh>
            <scale>1 1 1</scale>
            <uri>model://mobile_arm_bot_2/meshes/link_4.STL</uri>
          </mesh>
        </geometry>
      </collision>
      <visual name='link_4_visual'>
        <pose>0 0 0 0 -0 0</pose>
        <geometry>
          <mesh>
            <scale>1 1 1</scale>
            <uri>model://mobile_arm_bot_2/meshes/link_4.STL</uri>
          </mesh>
        </geometry>
      </visual>
    </link>
    <joint name='gripper_base_joint' type='revolute'>
      <pose relative_to='link_4'>0.039739 5e-05 0.004638 -0.025359 1.0602 -0.014195</pose>
      <parent>link_4</parent>
      <child>gripper_base_link</child>
      <axis>
        <xyz>0 0.99996 0.008727</xyz>
        <limit>
          <lower>0</lower>
          <upper>3.1416</upper>
          <effort>0</effort>
          <velocity>0</velocity>
        </limit>
        <dynamics>
          <spring_reference>0</spring_reference>
          <spring_stiffness>0</spring_stiffness>
        </dynamics>
      </axis>
    </joint>
    <link name='gripper_base_link'>
      <pose relative_to='gripper_base_joint'>0 0 0 0 -0 0</pose>
      <inertial>
        <pose>0.023551 -0.014074 0.005694 0 -0 0</pose>
        <mass>0.015721</mass>
        <inertia>
          <ixx>2.5605e-06</ixx>
          <ixy>-1.4166e-06</ixy>
          <ixz>-1.3765e-06</ixz>
          <iyy>7.2536e-06</iyy>
          <iyz>-3.5787e-07</iyz>
          <izz>8.1096e-06</izz>
        </inertia>
      </inertial>
      <collision name='gripper_base_link_collision'>
        <pose>0 0 0 0 -0 0</pose>
        <geometry>
          <mesh>
            <scale>1 1 1</scale>
            <uri>model://mobile_arm_bot_2/meshes/gripper_base_link.STL</uri>
          </mesh>
        </geometry>
      </collision>
      <visual name='gripper_base_link_visual'>
        <pose>0 0 0 0 -0 0</pose>
        <geometry>
          <mesh>
            <scale>1 1 1</scale>
            <uri>model://mobile_arm_bot_2/meshes/gripper_base_link.STL</uri>
          </mesh>
        </geometry>
      </visual>
    </link>
    <joint name='left_gear_joint' type='revolute'>
      <pose relative_to='gripper_base_link'>0.038 0.0019 1.7e-05 0.008722 -0.000289 0.033149</pose>
      <parent>gripper_base_link</parent>
      <child>left_gear_link</child>
      <axis>
        <xyz>0 0 1</xyz>
        <limit>
          <lower>0</lower>
          <upper>2</upper>
          <effort>5</effort>
          <velocity>0</velocity>
        </limit>
        <dynamics>
          <spring_reference>0</spring_reference>
          <spring_stiffness>0</spring_stiffness>
        </dynamics>
      </axis>
    </joint>
    <link name='left_gear_link'>
      <pose relative_to='left_gear_joint'>0 0 0 0 -0 0</pose>
      <inertial>
        <pose>0.005683 -0.000407 0.016 0 -0 0</pose>
        <mass>0.0025659</mass>
        <inertia>
          <ixx>9.0729e-08</ixx>
          <ixy>-1.9117e-08</ixy>
          <ixz>2.1722e-19</ixz>
          <iyy>3.6228e-07</iyy>
          <iyz>-4.5607e-20</iyz>
          <izz>4.4616e-07</izz>
        </inertia>
      </inertial>
      <collision name='left_gear_link_collision'>
        <pose>0 0 0 0 -0 0</pose>
        <geometry>
          <mesh>
            <scale>1 1 1</scale>
            <uri>model://mobile_arm_bot_2/meshes/left_gear_link.STL</uri>
          </mesh>
        </geometry>
      </collision>
      <visual name='left_gear_link_visual'>
        <pose>0 0 0 0 -0 0</pose>
        <geometry>
          <mesh>
            <scale>1 1 1</scale>
            <uri>model://mobile_arm_bot_2/meshes/left_gear_link.STL</uri>
          </mesh>
        </geometry>
      </visual>
    </link>
    <joint name='left_finger_joint' type='revolute'>
      <pose relative_to='left_gear_link'>0.030728 0.001075 0.013997 0 0 -0.4368</pose>
      <parent>left_gear_link</parent>
      <child>left_finger_link</child>
      <axis>
        <xyz>0 0 -1</xyz>
        <limit>
          <lower>0</lower>
          <upper>3.1416</upper>
          <effort>0</effort>
          <velocity>0</velocity>
        </limit>
        <dynamics>
          <spring_reference>0</spring_reference>
          <spring_stiffness>0</spring_stiffness>
        </dynamics>
      </axis>
    </joint>
    <link name='left_finger_link'>
      <pose relative_to='left_finger_joint'>0 0 0 0 -0 0</pose>
      <inertial>
        <pose>0.026893 0.004513 -0.004247 0 -0 0</pose>
        <mass>0.0053975</mass>
        <inertia>
          <ixx>1.8308e-07</ixx>
          <ixy>-3.7341e-07</ixy>
          <ixz>-6.5545e-12</ixz>
          <iyy>1.5958e-06</iyy>
          <iyz>1.2621e-11</iyz>
          <izz>1.7139e-06</izz>
        </inertia>
      </inertial>
      <collision name='left_finger_link_collision'>
        <pose>0 0 0 0 -0 0</pose>
        <geometry>
          <mesh>
            <scale>1 1 1</scale>
            <uri>model://mobile_arm_bot_2/meshes/left_finger_link.STL</uri>
          </mesh>
        </geometry>
      </collision>
      <visual name='left_finger_link_visual'>
        <pose>0 0 0 0 -0 0</pose>
        <geometry>
          <mesh>
            <scale>1 1 1</scale>
            <uri>model://mobile_arm_bot_2/meshes/left_finger_link.STL</uri>
          </mesh>
        </geometry>
      </visual>
    </link>
    <joint name='left_joint' type='revolute'>
      <pose relative_to='gripper_base_link'>0.058 -0.016986 -0.001653 0.008716 0.000422 -0.048378</pose>
      <parent>gripper_base_link</parent>
      <child>left_link</child>
      <axis>
        <xyz>0 0 -1</xyz>
        <limit>
          <lower>0</lower>
          <upper>3.1416</upper>
          <effort>0</effort>
          <velocity>0</velocity>
        </limit>
        <dynamics>
          <spring_reference>0</spring_reference>
          <spring_stiffness>0</spring_stiffness>
        </dynamics>
      </axis>
    </joint>
    <link name='left_link'>
      <pose relative_to='left_joint'>0 0 0 0 -0 0</pose>
      <inertial>
        <pose>0.0155 -0 0.017505 0 -0 0</pose>
        <mass>0.00079876</mass>
        <inertia>
          <ixx>3.6325e-09</ixx>
          <ixy>1.2874e-22</ixy>
          <ixz>-8.1684e-23</ixz>
          <iyy>1.0292e-07</iyy>
          <iyz>-6.2142e-22</iyz>
          <izz>1.0442e-07</izz>
        </inertia>
      </inertial>
      <collision name='left_link_collision'>
        <pose>0 0 0 0 -0 0</pose>
        <geometry>
          <mesh>
            <scale>1 1 1</scale>
            <uri>model://mobile_arm_bot_2/meshes/left_link.STL</uri>
          </mesh>
        </geometry>
      </collision>
      <visual name='left_link_visual'>
        <pose>0 0 0 0 -0 0</pose>
        <geometry>
          <mesh>
            <scale>1 1 1</scale>
            <uri>model://mobile_arm_bot_2/meshes/left_link.STL</uri>
          </mesh>
        </geometry>
      </visual>
    </link>
    <joint name='right_gear_joint' type='revolute'>
      <pose relative_to='gripper_base_link'>0.038 -0.024999 -0.000218 0.008708 0.000575 -0.06592</pose>
      <parent>gripper_base_link</parent>
      <child>right_gear_link</child>
      <axis>
        <xyz>0 0 -1</xyz>
        <limit>
          <lower>0</lower>
          <upper>3.1416</upper>
          <effort>0</effort>
          <velocity>0</velocity>
        </limit>
        <dynamics>
          <spring_reference>0</spring_reference>
          <spring_stiffness>0</spring_stiffness>
        </dynamics>
      </axis>
    </joint>
    <link name='right_gear_link'>
      <pose relative_to='right_gear_joint'>0 0 0 0 -0 0</pose>
      <inertial>
        <pose>0.005579 0.000602 0.016 0 -0 0</pose>
        <mass>0.0026416</mass>
        <inertia>
          <ixx>9.0046e-08</ixx>
          <ixy>9.2574e-09</ixy>
          <ixz>4.4469e-21</ixz>
          <iyy>3.6424e-07</iyy>
          <iyz>-3.7286e-20</iyz>
          <izz>4.4724e-07</izz>
        </inertia>
      </inertial>
      <collision name='right_gear_link_collision'>
        <pose>0 0 0 0 -0 0</pose>
        <geometry>
          <mesh>
            <scale>1 1 1</scale>
            <uri>model://mobile_arm_bot_2/meshes/right_gear_link.STL</uri>
          </mesh>
        </geometry>
      </collision>
      <visual name='right_gear_link_visual'>
        <pose>0 0 0 0 -0 0</pose>
        <geometry>
          <mesh>
            <scale>1 1 1</scale>
            <uri>model://mobile_arm_bot_2/meshes/right_gear_link.STL</uri>
          </mesh>
        </geometry>
      </visual>
    </link>
    <joint name='right_finger_joint' type='revolute'>
      <pose relative_to='right_gear_link'>0.030747 0 0.005503 3.14159 0 0.46391</pose>
      <parent>right_gear_link</parent>
      <child>right_finger_link</child>
      <axis>
        <xyz>0 0 -1</xyz>
        <limit>
          <lower>0</lower>
          <upper>3.1416</upper>
          <effort>0</effort>
          <velocity>0</velocity>
        </limit>
        <dynamics>
          <spring_reference>0</spring_reference>
          <spring_stiffness>0</spring_stiffness>
        </dynamics>
      </axis>
    </joint>
    <link name='right_finger_link'>
      <pose relative_to='right_finger_joint'>0 0 0 0 -0 0</pose>
      <inertial>
        <pose>0.026893 0.004513 -0.004247 0 -0 0</pose>
        <mass>0.0053975</mass>
        <inertia>
          <ixx>1.8308e-07</ixx>
          <ixy>-3.7341e-07</ixy>
          <ixz>-6.6286e-12</ixz>
          <iyy>1.5958e-06</iyy>
          <iyz>1.2817e-11</iyz>
          <izz>1.7139e-06</izz>
        </inertia>
      </inertial>
      <collision name='right_finger_link_collision'>
        <pose>0 0 0 0 -0 0</pose>
        <geometry>
          <mesh>
            <scale>1 1 1</scale>
            <uri>model://mobile_arm_bot_2/meshes/right_finger_link.STL</uri>
          </mesh>
        </geometry>
      </collision>
      <visual name='right_finger_link_visual'>
        <pose>0 0 0 0 -0 0</pose>
        <geometry>
          <mesh>
            <scale>1 1 1</scale>
            <uri>model://mobile_arm_bot_2/meshes/right_finger_link.STL</uri>
          </mesh>
        </geometry>
      </visual>
    </link>
    <joint name='right_joint' type='revolute'>
      <pose relative_to='gripper_base_link'>0.058 -0.006984 -0.001891 0.008701 -0.000662 0.07588</pose>
      <parent>gripper_base_link</parent>
      <child>right_link</child>
      <axis>
        <xyz>0 0 1</xyz>
        <limit>
          <lower>0</lower>
          <upper>2</upper>
          <effort>5</effort>
          <velocity>0</velocity>
        </limit>
        <dynamics>
          <spring_reference>0</spring_reference>
          <spring_stiffness>0</spring_stiffness>
        </dynamics>
      </axis>
    </joint>
    <link name='right_link'>
      <pose relative_to='right_joint'>0 0 0 0 -0 0</pose>
      <inertial>
        <pose>0.0155 -0 0.01783 0 -0 0</pose>
        <mass>0.00079876</mass>
        <inertia>
          <ixx>3.6325e-09</ixx>
          <ixy>-6.1069e-23</ixy>
          <ixz>-7.2482e-23</ixz>
          <iyy>1.0292e-07</iyy>
          <iyz>-6.2762e-22</iyz>
          <izz>1.0442e-07</izz>
        </inertia>
      </inertial>
      <collision name='right_link_collision'>
        <pose>0 0 0 0 -0 0</pose>
        <geometry>
          <mesh>
            <scale>1 1 1</scale>
            <uri>model://mobile_arm_bot_2/meshes/right_link.STL</uri>
          </mesh>
        </geometry>
      </collision>
      <visual name='right_link_visual'>
        <pose>0 0 0 0 -0 0</pose>
        <geometry>
          <mesh>
            <scale>1 1 1</scale>
            <uri>model://mobile_arm_bot_2/meshes/right_link.STL</uri>
          </mesh>
        </geometry>
      </visual>
    </link>
  </model>
</sdf>
